Internal Server Error: /detoxa-services/cart/get-cart-item/
Traceback (most recent call last):
  File "C:\Users\91991\AppData\Local\Programs\Python\Python310\lib\site-packages\jwt\api_jws.py", line 187, in _load
    signing_input, crypto_segment = jwt.rsplit(b".", 1)
ValueError: not enough values to unpack (expected 2, got 1)

The above exception was the direct cause of the following exception:

Traceback (most recent call last):
  File "C:\Users\91991\AppData\Local\Programs\Python\Python310\lib\site-packages\django\core\handlers\exception.py", line 47, in inner
    response = get_response(request)
  File "C:\Users\91991\AppData\Local\Programs\Python\Python310\lib\site-packages\django\core\handlers\base.py", line 181, in _get_response
    response = wrapped_callback(request, *callback_args, **callback_kwargs)
  File "C:\Users\91991\AppData\Local\Programs\Python\Python310\lib\site-packages\django\views\decorators\csrf.py", line 54, in wrapped_view
    return view_func(*args, **kwargs)
  File "C:\Users\91991\AppData\Local\Programs\Python\Python310\lib\site-packages\django\views\generic\base.py", line 70, in view
    return self.dispatch(request, *args, **kwargs)
  File "C:\Users\91991\AppData\Local\Programs\Python\Python310\lib\site-packages\rest_framework\views.py", line 509, in dispatch
    response = self.handle_exception(exc)
  File "C:\Users\91991\AppData\Local\Programs\Python\Python310\lib\site-packages\rest_framework\views.py", line 469, in handle_exception
    self.raise_uncaught_exception(exc)
  File "C:\Users\91991\AppData\Local\Programs\Python\Python310\lib\site-packages\rest_framework\views.py", line 480, in raise_uncaught_exception
    raise exc
  File "C:\Users\91991\AppData\Local\Programs\Python\Python310\lib\site-packages\rest_framework\views.py", line 497, in dispatch
    self.initial(request, *args, **kwargs)
  File "C:\Users\91991\AppData\Local\Programs\Python\Python310\lib\site-packages\rest_framework\views.py", line 414, in initial
    self.perform_authentication(request)
  File "C:\Users\91991\AppData\Local\Programs\Python\Python310\lib\site-packages\rest_framework\views.py", line 324, in perform_authentication
    request.user
  File "C:\Users\91991\AppData\Local\Programs\Python\Python310\lib\site-packages\rest_framework\request.py", line 227, in user
    self._authenticate()
  File "C:\Users\91991\AppData\Local\Programs\Python\Python310\lib\site-packages\rest_framework\request.py", line 380, in _authenticate
    user_auth_tuple = authenticator.authenticate(self)
  File "C:\folders\workspace\py\detoxa-backend-python-new\detoxa_services\utils\user_authentication.py", line 15, in authenticate
    decoded_token = jwt.decode(authorization_header, settings.JWT_SECRET_KEY, algorithms=['HS256'])
  File "C:\Users\91991\AppData\Local\Programs\Python\Python310\lib\site-packages\jwt\api_jwt.py", line 119, in decode
    decoded = self.decode_complete(jwt, key, algorithms, options, **kwargs)
  File "C:\Users\91991\AppData\Local\Programs\Python\Python310\lib\site-packages\jwt\api_jwt.py", line 90, in decode_complete
    decoded = api_jws.decode_complete(
  File "C:\Users\91991\AppData\Local\Programs\Python\Python310\lib\site-packages\jwt\api_jws.py", line 146, in decode_complete
    payload, signing_input, header, signature = self._load(jwt)
  File "C:\Users\91991\AppData\Local\Programs\Python\Python310\lib\site-packages\jwt\api_jws.py", line 190, in _load
    raise DecodeError("Not enough segments") from err
jwt.exceptions.DecodeError: Not enough segments
Internal Server Error: /detoxa-services/user/child
Traceback (most recent call last):
  File "C:\Users\91991\AppData\Local\Programs\Python\Python310\lib\site-packages\jwt\api_jws.py", line 187, in _load
    signing_input, crypto_segment = jwt.rsplit(b".", 1)
ValueError: not enough values to unpack (expected 2, got 1)

The above exception was the direct cause of the following exception:

Traceback (most recent call last):
  File "C:\Users\91991\AppData\Local\Programs\Python\Python310\lib\site-packages\django\core\handlers\exception.py", line 47, in inner
    response = get_response(request)
  File "C:\Users\91991\AppData\Local\Programs\Python\Python310\lib\site-packages\django\core\handlers\base.py", line 181, in _get_response
    response = wrapped_callback(request, *callback_args, **callback_kwargs)
  File "C:\Users\91991\AppData\Local\Programs\Python\Python310\lib\site-packages\django\views\decorators\csrf.py", line 54, in wrapped_view
    return view_func(*args, **kwargs)
  File "C:\Users\91991\AppData\Local\Programs\Python\Python310\lib\site-packages\django\views\generic\base.py", line 70, in view
    return self.dispatch(request, *args, **kwargs)
  File "C:\Users\91991\AppData\Local\Programs\Python\Python310\lib\site-packages\rest_framework\views.py", line 509, in dispatch
    response = self.handle_exception(exc)
  File "C:\Users\91991\AppData\Local\Programs\Python\Python310\lib\site-packages\rest_framework\views.py", line 469, in handle_exception
    self.raise_uncaught_exception(exc)
  File "C:\Users\91991\AppData\Local\Programs\Python\Python310\lib\site-packages\rest_framework\views.py", line 480, in raise_uncaught_exception
    raise exc
  File "C:\Users\91991\AppData\Local\Programs\Python\Python310\lib\site-packages\rest_framework\views.py", line 497, in dispatch
    self.initial(request, *args, **kwargs)
  File "C:\Users\91991\AppData\Local\Programs\Python\Python310\lib\site-packages\rest_framework\views.py", line 414, in initial
    self.perform_authentication(request)
  File "C:\Users\91991\AppData\Local\Programs\Python\Python310\lib\site-packages\rest_framework\views.py", line 324, in perform_authentication
    request.user
  File "C:\Users\91991\AppData\Local\Programs\Python\Python310\lib\site-packages\rest_framework\request.py", line 227, in user
    self._authenticate()
  File "C:\Users\91991\AppData\Local\Programs\Python\Python310\lib\site-packages\rest_framework\request.py", line 380, in _authenticate
    user_auth_tuple = authenticator.authenticate(self)
  File "C:\folders\workspace\py\detoxa-backend-python-new\detoxa_services\utils\user_authentication.py", line 15, in authenticate
    decoded_token = jwt.decode(authorization_header, settings.JWT_SECRET_KEY, algorithms=['HS256'])
  File "C:\Users\91991\AppData\Local\Programs\Python\Python310\lib\site-packages\jwt\api_jwt.py", line 119, in decode
    decoded = self.decode_complete(jwt, key, algorithms, options, **kwargs)
  File "C:\Users\91991\AppData\Local\Programs\Python\Python310\lib\site-packages\jwt\api_jwt.py", line 90, in decode_complete
    decoded = api_jws.decode_complete(
  File "C:\Users\91991\AppData\Local\Programs\Python\Python310\lib\site-packages\jwt\api_jws.py", line 146, in decode_complete
    payload, signing_input, header, signature = self._load(jwt)
  File "C:\Users\91991\AppData\Local\Programs\Python\Python310\lib\site-packages\jwt\api_jws.py", line 190, in _load
    raise DecodeError("Not enough segments") from err
jwt.exceptions.DecodeError: Not enough segments
Internal Server Error: /detoxa-services/cart/get-cart-item/
Traceback (most recent call last):
  File "C:\Users\91991\AppData\Local\Programs\Python\Python310\lib\site-packages\jwt\api_jws.py", line 187, in _load
    signing_input, crypto_segment = jwt.rsplit(b".", 1)
ValueError: not enough values to unpack (expected 2, got 1)

The above exception was the direct cause of the following exception:

Traceback (most recent call last):
  File "C:\Users\91991\AppData\Local\Programs\Python\Python310\lib\site-packages\django\core\handlers\exception.py", line 47, in inner
    response = get_response(request)
  File "C:\Users\91991\AppData\Local\Programs\Python\Python310\lib\site-packages\django\core\handlers\base.py", line 181, in _get_response
    response = wrapped_callback(request, *callback_args, **callback_kwargs)
  File "C:\Users\91991\AppData\Local\Programs\Python\Python310\lib\site-packages\django\views\decorators\csrf.py", line 54, in wrapped_view
    return view_func(*args, **kwargs)
  File "C:\Users\91991\AppData\Local\Programs\Python\Python310\lib\site-packages\django\views\generic\base.py", line 70, in view
    return self.dispatch(request, *args, **kwargs)
  File "C:\Users\91991\AppData\Local\Programs\Python\Python310\lib\site-packages\rest_framework\views.py", line 509, in dispatch
    response = self.handle_exception(exc)
  File "C:\Users\91991\AppData\Local\Programs\Python\Python310\lib\site-packages\rest_framework\views.py", line 469, in handle_exception
    self.raise_uncaught_exception(exc)
  File "C:\Users\91991\AppData\Local\Programs\Python\Python310\lib\site-packages\rest_framework\views.py", line 480, in raise_uncaught_exception
    raise exc
  File "C:\Users\91991\AppData\Local\Programs\Python\Python310\lib\site-packages\rest_framework\views.py", line 497, in dispatch
    self.initial(request, *args, **kwargs)
  File "C:\Users\91991\AppData\Local\Programs\Python\Python310\lib\site-packages\rest_framework\views.py", line 414, in initial
    self.perform_authentication(request)
  File "C:\Users\91991\AppData\Local\Programs\Python\Python310\lib\site-packages\rest_framework\views.py", line 324, in perform_authentication
    request.user
  File "C:\Users\91991\AppData\Local\Programs\Python\Python310\lib\site-packages\rest_framework\request.py", line 227, in user
    self._authenticate()
  File "C:\Users\91991\AppData\Local\Programs\Python\Python310\lib\site-packages\rest_framework\request.py", line 380, in _authenticate
    user_auth_tuple = authenticator.authenticate(self)
  File "C:\folders\workspace\py\detoxa-backend-python-new\detoxa_services\utils\user_authentication.py", line 15, in authenticate
    decoded_token = jwt.decode(authorization_header, settings.JWT_SECRET_KEY, algorithms=['HS256'])
  File "C:\Users\91991\AppData\Local\Programs\Python\Python310\lib\site-packages\jwt\api_jwt.py", line 119, in decode
    decoded = self.decode_complete(jwt, key, algorithms, options, **kwargs)
  File "C:\Users\91991\AppData\Local\Programs\Python\Python310\lib\site-packages\jwt\api_jwt.py", line 90, in decode_complete
    decoded = api_jws.decode_complete(
  File "C:\Users\91991\AppData\Local\Programs\Python\Python310\lib\site-packages\jwt\api_jws.py", line 146, in decode_complete
    payload, signing_input, header, signature = self._load(jwt)
  File "C:\Users\91991\AppData\Local\Programs\Python\Python310\lib\site-packages\jwt\api_jws.py", line 190, in _load
    raise DecodeError("Not enough segments") from err
jwt.exceptions.DecodeError: Not enough segments
Internal Server Error: /detoxa-services/user/child
Traceback (most recent call last):
  File "C:\Users\91991\AppData\Local\Programs\Python\Python310\lib\site-packages\jwt\api_jws.py", line 187, in _load
    signing_input, crypto_segment = jwt.rsplit(b".", 1)
ValueError: not enough values to unpack (expected 2, got 1)

The above exception was the direct cause of the following exception:

Traceback (most recent call last):
  File "C:\Users\91991\AppData\Local\Programs\Python\Python310\lib\site-packages\django\core\handlers\exception.py", line 47, in inner
    response = get_response(request)
  File "C:\Users\91991\AppData\Local\Programs\Python\Python310\lib\site-packages\django\core\handlers\base.py", line 181, in _get_response
    response = wrapped_callback(request, *callback_args, **callback_kwargs)
  File "C:\Users\91991\AppData\Local\Programs\Python\Python310\lib\site-packages\django\views\decorators\csrf.py", line 54, in wrapped_view
    return view_func(*args, **kwargs)
  File "C:\Users\91991\AppData\Local\Programs\Python\Python310\lib\site-packages\django\views\generic\base.py", line 70, in view
    return self.dispatch(request, *args, **kwargs)
  File "C:\Users\91991\AppData\Local\Programs\Python\Python310\lib\site-packages\rest_framework\views.py", line 509, in dispatch
    response = self.handle_exception(exc)
  File "C:\Users\91991\AppData\Local\Programs\Python\Python310\lib\site-packages\rest_framework\views.py", line 469, in handle_exception
    self.raise_uncaught_exception(exc)
  File "C:\Users\91991\AppData\Local\Programs\Python\Python310\lib\site-packages\rest_framework\views.py", line 480, in raise_uncaught_exception
    raise exc
  File "C:\Users\91991\AppData\Local\Programs\Python\Python310\lib\site-packages\rest_framework\views.py", line 497, in dispatch
    self.initial(request, *args, **kwargs)
  File "C:\Users\91991\AppData\Local\Programs\Python\Python310\lib\site-packages\rest_framework\views.py", line 414, in initial
    self.perform_authentication(request)
  File "C:\Users\91991\AppData\Local\Programs\Python\Python310\lib\site-packages\rest_framework\views.py", line 324, in perform_authentication
    request.user
  File "C:\Users\91991\AppData\Local\Programs\Python\Python310\lib\site-packages\rest_framework\request.py", line 227, in user
    self._authenticate()
  File "C:\Users\91991\AppData\Local\Programs\Python\Python310\lib\site-packages\rest_framework\request.py", line 380, in _authenticate
    user_auth_tuple = authenticator.authenticate(self)
  File "C:\folders\workspace\py\detoxa-backend-python-new\detoxa_services\utils\user_authentication.py", line 15, in authenticate
    decoded_token = jwt.decode(authorization_header, settings.JWT_SECRET_KEY, algorithms=['HS256'])
  File "C:\Users\91991\AppData\Local\Programs\Python\Python310\lib\site-packages\jwt\api_jwt.py", line 119, in decode
    decoded = self.decode_complete(jwt, key, algorithms, options, **kwargs)
  File "C:\Users\91991\AppData\Local\Programs\Python\Python310\lib\site-packages\jwt\api_jwt.py", line 90, in decode_complete
    decoded = api_jws.decode_complete(
  File "C:\Users\91991\AppData\Local\Programs\Python\Python310\lib\site-packages\jwt\api_jws.py", line 146, in decode_complete
    payload, signing_input, header, signature = self._load(jwt)
  File "C:\Users\91991\AppData\Local\Programs\Python\Python310\lib\site-packages\jwt\api_jws.py", line 190, in _load
    raise DecodeError("Not enough segments") from err
jwt.exceptions.DecodeError: Not enough segments
Internal Server Error: /detoxa-services/cart/get-cart-item/
Traceback (most recent call last):
  File "C:\Users\91991\AppData\Local\Programs\Python\Python310\lib\site-packages\jwt\api_jws.py", line 187, in _load
    signing_input, crypto_segment = jwt.rsplit(b".", 1)
ValueError: not enough values to unpack (expected 2, got 1)

The above exception was the direct cause of the following exception:

Traceback (most recent call last):
  File "C:\Users\91991\AppData\Local\Programs\Python\Python310\lib\site-packages\django\core\handlers\exception.py", line 47, in inner
    response = get_response(request)
  File "C:\Users\91991\AppData\Local\Programs\Python\Python310\lib\site-packages\django\core\handlers\base.py", line 181, in _get_response
    response = wrapped_callback(request, *callback_args, **callback_kwargs)
  File "C:\Users\91991\AppData\Local\Programs\Python\Python310\lib\site-packages\django\views\decorators\csrf.py", line 54, in wrapped_view
    return view_func(*args, **kwargs)
  File "C:\Users\91991\AppData\Local\Programs\Python\Python310\lib\site-packages\django\views\generic\base.py", line 70, in view
    return self.dispatch(request, *args, **kwargs)
  File "C:\Users\91991\AppData\Local\Programs\Python\Python310\lib\site-packages\rest_framework\views.py", line 509, in dispatch
    response = self.handle_exception(exc)
  File "C:\Users\91991\AppData\Local\Programs\Python\Python310\lib\site-packages\rest_framework\views.py", line 469, in handle_exception
    self.raise_uncaught_exception(exc)
  File "C:\Users\91991\AppData\Local\Programs\Python\Python310\lib\site-packages\rest_framework\views.py", line 480, in raise_uncaught_exception
    raise exc
  File "C:\Users\91991\AppData\Local\Programs\Python\Python310\lib\site-packages\rest_framework\views.py", line 497, in dispatch
    self.initial(request, *args, **kwargs)
  File "C:\Users\91991\AppData\Local\Programs\Python\Python310\lib\site-packages\rest_framework\views.py", line 414, in initial
    self.perform_authentication(request)
  File "C:\Users\91991\AppData\Local\Programs\Python\Python310\lib\site-packages\rest_framework\views.py", line 324, in perform_authentication
    request.user
  File "C:\Users\91991\AppData\Local\Programs\Python\Python310\lib\site-packages\rest_framework\request.py", line 227, in user
    self._authenticate()
  File "C:\Users\91991\AppData\Local\Programs\Python\Python310\lib\site-packages\rest_framework\request.py", line 380, in _authenticate
    user_auth_tuple = authenticator.authenticate(self)
  File "C:\folders\workspace\py\detoxa-backend-python-new\detoxa_services\utils\user_authentication.py", line 15, in authenticate
    decoded_token = jwt.decode(authorization_header, settings.JWT_SECRET_KEY, algorithms=['HS256'])
  File "C:\Users\91991\AppData\Local\Programs\Python\Python310\lib\site-packages\jwt\api_jwt.py", line 119, in decode
    decoded = self.decode_complete(jwt, key, algorithms, options, **kwargs)
  File "C:\Users\91991\AppData\Local\Programs\Python\Python310\lib\site-packages\jwt\api_jwt.py", line 90, in decode_complete
    decoded = api_jws.decode_complete(
  File "C:\Users\91991\AppData\Local\Programs\Python\Python310\lib\site-packages\jwt\api_jws.py", line 146, in decode_complete
    payload, signing_input, header, signature = self._load(jwt)
  File "C:\Users\91991\AppData\Local\Programs\Python\Python310\lib\site-packages\jwt\api_jws.py", line 190, in _load
    raise DecodeError("Not enough segments") from err
jwt.exceptions.DecodeError: Not enough segments
Invalid HTTP_HOST header: 'localhost:8000'. You may need to add 'localhost' to ALLOWED_HOSTS.
Invalid HTTP_HOST header: 'localhost:8000'. You may need to add 'localhost' to ALLOWED_HOSTS.
Internal Server Error: /detoxa-services/cart/get-cart-item/
Traceback (most recent call last):
  File "C:\Users\91991\AppData\Local\Programs\Python\Python310\lib\site-packages\jwt\api_jws.py", line 187, in _load
    signing_input, crypto_segment = jwt.rsplit(b".", 1)
ValueError: not enough values to unpack (expected 2, got 1)

The above exception was the direct cause of the following exception:

Traceback (most recent call last):
  File "C:\Users\91991\AppData\Local\Programs\Python\Python310\lib\site-packages\django\core\handlers\exception.py", line 47, in inner
    response = get_response(request)
  File "C:\Users\91991\AppData\Local\Programs\Python\Python310\lib\site-packages\django\core\handlers\base.py", line 181, in _get_response
    response = wrapped_callback(request, *callback_args, **callback_kwargs)
  File "C:\Users\91991\AppData\Local\Programs\Python\Python310\lib\site-packages\django\views\decorators\csrf.py", line 54, in wrapped_view
    return view_func(*args, **kwargs)
  File "C:\Users\91991\AppData\Local\Programs\Python\Python310\lib\site-packages\django\views\generic\base.py", line 70, in view
    return self.dispatch(request, *args, **kwargs)
  File "C:\Users\91991\AppData\Local\Programs\Python\Python310\lib\site-packages\rest_framework\views.py", line 509, in dispatch
    response = self.handle_exception(exc)
  File "C:\Users\91991\AppData\Local\Programs\Python\Python310\lib\site-packages\rest_framework\views.py", line 469, in handle_exception
    self.raise_uncaught_exception(exc)
  File "C:\Users\91991\AppData\Local\Programs\Python\Python310\lib\site-packages\rest_framework\views.py", line 480, in raise_uncaught_exception
    raise exc
  File "C:\Users\91991\AppData\Local\Programs\Python\Python310\lib\site-packages\rest_framework\views.py", line 497, in dispatch
    self.initial(request, *args, **kwargs)
  File "C:\Users\91991\AppData\Local\Programs\Python\Python310\lib\site-packages\rest_framework\views.py", line 414, in initial
    self.perform_authentication(request)
  File "C:\Users\91991\AppData\Local\Programs\Python\Python310\lib\site-packages\rest_framework\views.py", line 324, in perform_authentication
    request.user
  File "C:\Users\91991\AppData\Local\Programs\Python\Python310\lib\site-packages\rest_framework\request.py", line 227, in user
    self._authenticate()
  File "C:\Users\91991\AppData\Local\Programs\Python\Python310\lib\site-packages\rest_framework\request.py", line 380, in _authenticate
    user_auth_tuple = authenticator.authenticate(self)
  File "C:\folders\workspace\py\detoxa-backend-python-new\detoxa_services\utils\user_authentication.py", line 15, in authenticate
    decoded_token = jwt.decode(authorization_header, settings.JWT_SECRET_KEY, algorithms=['HS256'])
  File "C:\Users\91991\AppData\Local\Programs\Python\Python310\lib\site-packages\jwt\api_jwt.py", line 119, in decode
    decoded = self.decode_complete(jwt, key, algorithms, options, **kwargs)
  File "C:\Users\91991\AppData\Local\Programs\Python\Python310\lib\site-packages\jwt\api_jwt.py", line 90, in decode_complete
    decoded = api_jws.decode_complete(
  File "C:\Users\91991\AppData\Local\Programs\Python\Python310\lib\site-packages\jwt\api_jws.py", line 146, in decode_complete
    payload, signing_input, header, signature = self._load(jwt)
  File "C:\Users\91991\AppData\Local\Programs\Python\Python310\lib\site-packages\jwt\api_jws.py", line 190, in _load
    raise DecodeError("Not enough segments") from err
jwt.exceptions.DecodeError: Not enough segments
Internal Server Error: /detoxa-services/cart/get-cart-item/
Traceback (most recent call last):
  File "C:\Users\91991\AppData\Local\Programs\Python\Python310\lib\site-packages\jwt\api_jws.py", line 187, in _load
    signing_input, crypto_segment = jwt.rsplit(b".", 1)
ValueError: not enough values to unpack (expected 2, got 1)

The above exception was the direct cause of the following exception:

Traceback (most recent call last):
  File "C:\Users\91991\AppData\Local\Programs\Python\Python310\lib\site-packages\django\core\handlers\exception.py", line 47, in inner
    response = get_response(request)
  File "C:\Users\91991\AppData\Local\Programs\Python\Python310\lib\site-packages\django\core\handlers\base.py", line 181, in _get_response
    response = wrapped_callback(request, *callback_args, **callback_kwargs)
  File "C:\Users\91991\AppData\Local\Programs\Python\Python310\lib\site-packages\django\views\decorators\csrf.py", line 54, in wrapped_view
    return view_func(*args, **kwargs)
  File "C:\Users\91991\AppData\Local\Programs\Python\Python310\lib\site-packages\django\views\generic\base.py", line 70, in view
    return self.dispatch(request, *args, **kwargs)
  File "C:\Users\91991\AppData\Local\Programs\Python\Python310\lib\site-packages\rest_framework\views.py", line 509, in dispatch
    response = self.handle_exception(exc)
  File "C:\Users\91991\AppData\Local\Programs\Python\Python310\lib\site-packages\rest_framework\views.py", line 469, in handle_exception
    self.raise_uncaught_exception(exc)
  File "C:\Users\91991\AppData\Local\Programs\Python\Python310\lib\site-packages\rest_framework\views.py", line 480, in raise_uncaught_exception
    raise exc
  File "C:\Users\91991\AppData\Local\Programs\Python\Python310\lib\site-packages\rest_framework\views.py", line 497, in dispatch
    self.initial(request, *args, **kwargs)
  File "C:\Users\91991\AppData\Local\Programs\Python\Python310\lib\site-packages\rest_framework\views.py", line 414, in initial
    self.perform_authentication(request)
  File "C:\Users\91991\AppData\Local\Programs\Python\Python310\lib\site-packages\rest_framework\views.py", line 324, in perform_authentication
    request.user
  File "C:\Users\91991\AppData\Local\Programs\Python\Python310\lib\site-packages\rest_framework\request.py", line 227, in user
    self._authenticate()
  File "C:\Users\91991\AppData\Local\Programs\Python\Python310\lib\site-packages\rest_framework\request.py", line 380, in _authenticate
    user_auth_tuple = authenticator.authenticate(self)
  File "C:\folders\workspace\py\detoxa-backend-python-new\detoxa_services\utils\user_authentication.py", line 15, in authenticate
    decoded_token = jwt.decode(authorization_header, settings.JWT_SECRET_KEY, algorithms=['HS256'])
  File "C:\Users\91991\AppData\Local\Programs\Python\Python310\lib\site-packages\jwt\api_jwt.py", line 119, in decode
    decoded = self.decode_complete(jwt, key, algorithms, options, **kwargs)
  File "C:\Users\91991\AppData\Local\Programs\Python\Python310\lib\site-packages\jwt\api_jwt.py", line 90, in decode_complete
    decoded = api_jws.decode_complete(
  File "C:\Users\91991\AppData\Local\Programs\Python\Python310\lib\site-packages\jwt\api_jws.py", line 146, in decode_complete
    payload, signing_input, header, signature = self._load(jwt)
  File "C:\Users\91991\AppData\Local\Programs\Python\Python310\lib\site-packages\jwt\api_jws.py", line 190, in _load
    raise DecodeError("Not enough segments") from err
jwt.exceptions.DecodeError: Not enough segments
Invalid HTTP_HOST header: 'localhost:8000'. You may need to add 'localhost' to ALLOWED_HOSTS.
Invalid HTTP_HOST header: 'localhost:8000'. You may need to add 'localhost' to ALLOWED_HOSTS.
Invalid HTTP_HOST header: 'localhost:8000'. You may need to add 'localhost' to ALLOWED_HOSTS.
